Workbook

Sheet Master Database
A1: ID | B1: Compound (EN) | C1: Compound (AR) | D1: City | E1: District | F1: Address | G1: Google Maps | H1: Latitude | I1: Longitude | J1: Compound Type | K1: Category | L1: Status | M1: Opened | N1: Units | O1: Unit Types | P1: Facilities | Q1: Website | R1: Main Phone | S1: Mobile | T1: WhatsApp | U1: Emails | V1: Instagram | W1: Facebook | X1: LinkedIn | Y1: Other Social | Z1: Owner | AA1: Developer | AB1: Property Manager / Operator | AC1: Management Type | AD1: Ownership Source | AE1: Contact Verification | AF1: Opportunities | AG1: Size (20) | AH1: Fit (25) | AI1: Need (20) | AJ1: Contact (15) | AK1: Party (10) | AL1: Collab (10) | AM1: Lead Score | AN1: Priority | AO1: Notes | AP1: Sources | AQ1: Last Checked
A2: KHB-001 | B2: Canary Village | D2: Al Khobar | F2: KSA | G2: Open map | H2: 26.349239 | I2: 50.186673 | J2: Villa Compound | K2: Residential compound | L2: Operating (listed) | N2: 159 | O2: Furnished 3-bed villas | P2: Gym Swimming Pool Reserved Parking Baby Nursery Beauty Salon Restaurant Ballroom Billiard Tables Squash Court Basketball Court Volleyball Court Wireless Internet Tennis Court Satellite Cable Pre-school Centre Recreational Room Table Tennis Bus Transp | Q2: https://www.canaryvillage.com/ | R2: +966138590895 | S2: +966534022218 | U2: leasing@canaryvillage.com ; rental.office@canaryvillage.com | V2: https://www.instagram.com/canaryvillage | W2: https://www.facebook.com/canary.canary.714 | Y2: https://twitter.com/canaryvillage | Z2: Rashed Al Rashed & Sons Group | AC2: Owner Managed | AD2: https://rightcompound.com/compounds/khobar/canary-village | AE2: Verified | AF2: Property management, Marketing & leasing, Paid ad campaigns | AG2: 15 | AH2: 8 | AI2: 6 | AJ2: 15 | AK2: 10 | AL2: 5 | AM2: =SUM(AG2:AL2) -> 59 | AN2: =IF(AM2>=80,"A",IF(AM2>=60,"B","C")) -> C | AP2: https://rightcompound.com/compounds/khobar/canary-village ; https://whichschooladvisor.com/saudi/area-guide/eastern-province/al-khobar ; https://www.expat.com/en/forum/middle-east/saudi-arabia/khobar/778968-list-of-some-compounds-in-al-khobar-ksa.html ; https://www.canaryvillage.com/ | AQ2: 2026-10-11
A3: KHB-002 | B3: Canary Vista | D3: Al Khobar | E3: Al Maha / Al Aziziyah | J3: Villa Compound | K3: Residential compound | L3: Operating (listed) | N3: 326 | O3: Villas | Q3: https://canary-vista.com/ | R3: +966138494999 | S3: +966534022276 | U3: rentaloffice@canaryvista.com | V3: https://instagram.com/canaryvistacommunity | W3: https://www.facebook.com/2070283359669619 | AC3: Unknown | AE3: Verified | AF3: Property management, Marketing & leasing, Paid ad campaigns | AG3: 20 | AH3: 8 | AI3: 6 | AJ3: 15 | AK3: 0 | AL3: 0 | AM3: =SUM(AG3:AL3) -> 49 | AN3: =IF(AM3>=80,"A",IF(AM3>=60,"B","C")) -> C | AO3: Former owner Qatif Concessions Management Co. (ExxonMobil) until 2007 per WhichSchoolAdvisor; current owner not confirmed. Same 013 849 4999 number also appears on a Dhahran Tower Beach listing. | AP3: https://whichschooladvisor.com/saudi/area-guide/eastern-province/al-khobar ; https://compoundin.com/compounds/khobar/canary-vista ; https://canary-vista.com/ | AQ3: 2026-10-11
A4: KHB-003 | B4: Eurovillage | D4: Al Khobar | E4: Prince Sultan Road (central Khobar) | J4: Villa Compound | K4: Residential compound | L4: Operating (listed) | N4: 560 | O4: Villas | Q4: https://www.eurovillage.sa/ | R4: 0138579780 | V4: https://www.instagram.com/eurovillage_compound | W4: https://www.facebook.com/EuroVillageSA | X4: https://www.linkedin.com/company/eurovillage-compound | AC4: Unknown | AE4: Verified | AF4: Property management, Paid ad campaigns | AG4: 20 | AH4: 8 | AI4: 0 | AJ4: 10 | AK4: 0 | AL4: 0 | AM4: =SUM(AG4:AL4) -> 38 | AN4: =IF(AM4>=80,"A",IF(AM4>=60,"B","C")) -> C | AO4: 'Over 560 villas' per expat guides; unit count not stated on official site. | AP4: https://soulofsaudi.com/best-compounds-in-saudi-arabia-for-expats/ ; https://www.expat.com/en/forum/middle-east/saudi-arabia/khobar/778968-list-of-some-compounds-in-al-khobar-ksa.html ; https://www.eurovillage.sa/contact/ | AQ4: 2026-10-11
A5: KHB-004 | B5: Las Dunas Compound | D5: Al Khobar | E5: Ar Rawabi | J5: Villa Compound | K5: Residential compound | L5: Operating (listed) | Q5: https://www.lasdunas-sa.com/ | S5: +966505876327 | U5: info@lasdunas-sa.com | AC5: Unknown | AE5: Verified | AF5: Property management, Marketing & leasing, Social media management | AG5: 0 | AH5: 8 | AI5: 6 | AJ5: 15 | AK5: 0 | AL5: 0 | AM5: =SUM(AG5:AL5) -> 29 | AN5: =IF(AM5>=80,"A",IF(AM5>=60,"B","C")) -> C | AP5: https://whichschooladvisor.com/saudi/area-guide/eastern-province/al-khobar ; https://www.lasdunas-sa.com/ | AQ5: 2026-10-11
A6: KHB-005 | B6: Riviera Waterfront Village | C6: ريفييرا قرية الواجهة البحرية | D6: Al Khobar | E6: Ishbiliya | F6: Ishbiliya, Al Khobar 34712 | G6: Open map | H6: 26.200206 | I6: 50.216558 | J6: Luxury Residential Compound | K6: Residential compound | L6: Operating (listed) | O6: Studios, 1-3 bed apartments, villas | P6: Gym Swimming Pool Kindergarten Reserved Parking Baby Nursery Beauty Salon Restaurant Ballroom Snack Bar Billiard Tables Squash Court Basketball Court Wireless Internet Tennis Court Satellite Cable Commercial Centre Recreational Room Business Centre T | Q6: https://www.rivieracompound.com/ | R6: 0138193555 | S6: 0580875741 | V6: https://www.instagram.com/rivieracompound | W6: https://www.facebook.com/Rivieracompoundsa | X6: https://www.linkedin.com/showcase/rivieracompound | Y6: https://www.snapchat.com/add/compoundriviera ; https://twitter.com/RivieraCompound | AC6: Unknown | AE6: Verified | AF6: Property management, Marketing & leasing, Paid ad campaigns | AG6: 0 | AH6: 8 | AI6: 6 | AJ6: 10 | AK6: 0 | AL6: 5 | AM6: =SUM(AG6:AL6) -> 29 | AN6: =IF(AM6>=80,"A",IF(AM6>=60,"B","C")) -> C | AP6: https://rightcompound.com/compounds/khobar/riviera-waterfront-village ; https://whichschooladvisor.com/saudi/area-guide/eastern-province/al-khobar ; https://www.rivieracompound.com/ | AQ6: 2026-10-11
A7: KHB-006 | B7: Al Mohamadia Compound | C7: مجمع المحمدية | D7: Al Khobar | E7: Al Sadafah | F7: Al Khobar | G7: Open map | H7: 26.366418 | I7: 50.210438 | J7: Mixed Residential Compound | K7: Residential compound | L7: Operating (listed) | N7: 262 | O7: Villas, apartments, studios | P7: Gym Swimming Pool Reserved Parking Baby Nursery Beauty Salon Restaurant Snack Bar Billiard Tables Basketball Court Volleyball Court Wireless Internet Tennis Court Satellite Cable Recreational Room Table Tennis Bus Transportation | Q7: https://www.al-othman.com/ar/al-mohamadia-compound | R7: +966138142288 | U7: info@al-othman.com | V7: https://instagram.com/alothman.holding | W7: https://www.facebook.com/pages/AlOthman-Holding/1492267767733144 | X7: https://www.linkedin.com/company/al--othman-holding-company | Z7: Al Othman Holding Company | AB7: Al Othman Holding Company | AC7: Owner Managed | AD7: https://rightcompound.com/compounds/khobar/mohamadia-compound | AE7: Verified | AF7: Property management, Marketing & leasing, Paid ad campaigns | AG7: 20 | AH7: 8 | AI7: 6 | AJ7: 15 | AK7: 10 | AL7: 5 | AM7: =SUM(AG7:AL7) -> 64 | AN7: =IF(AM7>=80,"A",IF(AM7>=60,"B","C")) -> B | AO7: Unit count differs: 262 (Property Finder), 96 (RightCompound), 1,152 (WhichSchoolAdvisor). Contacts are the holding company's. | AP7: https://rightcompound.com/compounds/khobar/mohamadia-compound ; https://www.propertyfinder.sa/blog/%D9%83%D9%85%D8%A8%D9%88%D9%86%D8%AF%D8%A7%D8%AA-%D8%A7%D9%84%D8%AE%D8%A8%D8%B1-%D9%85%D8%AC%D9%85%D8%B9%D8%A7%D8%AA-%D8%B3%D9%83%D9%86%D9%8A%D8%A9-%D8%B9%D8%A7%D9%84%D9%85%D9%8A%D8%A9-%D8%B9%D9%84/ ; https://whichschooladvisor.com/saudi/area-guide/eastern-province/al-khobar ; https://www.al-othman.com/ar/al-mohamadia-compound | AQ7: 2026-10-11
A8: KHB-007 | B8: Zamil Village | D8: Al Khobar | E8: Al Qashlah | F8: 958F+CJ8, Al Qashlah, Al Khobar 34232 | G8: Open map | H8: 26.367623 | I8: 50.17397 | J8: Mixed Residential Compound | K8: Residential compound | L8: Operating (listed) | N8: 254 | O8: 168 apartments, 86 villas | P8: Gym Swimming Pool Kindergarten Reserved Parking Baby Nursery Library Beauty Salon Restaurant Ballroom Snack Bar Billiard Tables Squash Court Basketball Court Volleyball Court Wireless Internet Tennis Court Satellite Cable Pre-school Centre Recreation | Q8: https://zamilrealestate.com/en | R8: +966138136225 | T8: +966138136225 | U8: info@zamilre.com ; marketing@zamilre.com | Y8: https://x.com/ZamilGroup | Z8: Zamil Real Estate | AB8: Zamil Real Estate | AC8: Developer Managed | AD8: https://whichschooladvisor.com/saudi/area-guide/eastern-province/al-khobar | AE8: Verified | AF8: Marketing & leasing, Paid ad campaigns | AG8: 20 | AH8: 8 | AI8: 6 | AJ8: 15 | AK8: 10 | AL8: 5 | AM8: =SUM(AG8:AL8) -> 64 | AN8: =IF(AM8>=80,"A",IF(AM8>=60,"B","C")) -> B | AP8: https://rightcompound.com/compounds/khobar/zamil-village-residential-compound ; https://whichschooladvisor.com/saudi/area-guide/eastern-province/al-khobar ; https://zamilrealestate.com/en | AQ8: 2026-10-11
A9: KHB-008 | B9: Wadi Village | D9: Al Khobar | E9: Qurtubah | F9: Al Khobar | G9: Open map | H9: 26.249144 | I9: 50.160377 | J9: Luxury Residential Compound | K9: Residential compound | L9: Operating (listed) | N9: 52 | O9: Villas and apartments | P9: Gym Swimming Pool Reserved Parking Library Restaurant Billiard Tables Squash Court Basketball Court Volleyball Court Wireless Internet Tennis Court Satellite Cable Recreational Room Table Tennis Bus Transportation Garbage Chute Children Playground Pe | AC9: Third-Party Property Management | AE9: Not Available | AF9: Marketing & leasing, Social media management, Content & photography | AG9: 10 | AH9: 8 | AI9: 20 | AJ9: 0 | AK9: 0 | AL9: 5 | AM9: =SUM(AG9:AL9) -> 43 | AN9: =IF(AM9>=80,"A",IF(AM9>=60,"B","C")) -> C | AO9: WhichSchoolAdvisor says 'British management' (unnamed) and links to zamilrealestate.com; operator not confirmed. | AP9: https://rightcompound.com/compounds/khobar/al-wadi-village ; https://whichschooladvisor.com/saudi/area-guide/eastern-province/al-khobar | AQ9: 2026-10-11
A10: KHB-009 | B10: Arabian Village (Arabian Homes) | D10: Al Khobar | E10: Qurtubah | F10: Qutuba district , Al Khobar | G10: Open map | H10: 26.336099 | I10: 50.181813 | J10: Mixed Residential Compound | K10: Residential compound | L10: Operating (listed) | M10: 2008 | N10: 134 | O10: 108 apartments, 26 villas | P10: Gym Swimming Pool Reserved Parking Baby Nursery Library Restaurant Billiard Tables Squash Court Basketball Court Volleyball Court Wireless Internet Tennis Court Satellite Cable Recreational Room Table Tennis Bus Transportation Garbage Chute Children | AC10: Third-Party Property Management | AE10: Not Available | AF10: Marketing & leasing, Social media management, Content & photography | AG10: 15 | AH10: 8 | AI10: 20 | AJ10: 0 | AK10: 0 | AL10: 5 | AM10: =SUM(AG10:AL10) -> 48 | AN10: =IF(AM10>=80,"A",IF(AM10>=60,"B","C")) -> C | AO10: Units: 134 (WhichSchoolAdvisor) vs 126 (RightCompound). 'Managed by a British team' (unnamed). | AP10: https://rightcompound.com/compounds/khobar/arabian-homes-al-khobar ; https://whichschooladvisor.com/saudi/area-guide/eastern-province/al-khobar | AQ10: 2026-10-11
A11: KHB-010 | B11: Retal Residence | D11: Al Khobar | E11: Al Rakah | F11: Retal Residence - 9268 Salma Bin Suliman Str. | G11: Open map | H11: 26.377357 | I11: 50.218291 | J11: Mixed Residential Compound | K11: Residential compound | L11: Operating (listed) | P11: Gym Swimming Pool Kindergarten Reserved Parking Baby Nursery Library Beauty Salon Restaurant Ballroom Snack Bar Billiard Tables Squash Court Basketball Court Volleyball Court Wireless Internet Tennis Court Satellite Cable Pre-school Centre Commercial | Q11: https://www.retalresidence.com/ | R11: +966138259600 | T11: +966562416136 | U11: info@retalresidence.com ; sales@retalresidence.com | AC11: Unknown | AE11: Verified | AF11: Property management, Marketing & leasing, Social media management | AG11: 0 | AH11: 8 | AI11: 12 | AJ11: 15 | AK11: 0 | AL11: 5 | AM11: =SUM(AG11:AL11) -> 40 | AN11: =IF(AM11>=80,"A",IF(AM11>=60,"B","C")) -> C | AP11: https://rightcompound.com/compounds/khobar/retal-residence ; https://compoundin.com/rent/listing/1/0/0-0 ; https://www.retalresidence.com/ | AQ11: 2026-10-11
A12: KHB-011 | B12: Grand Village | C12: جراند فيلج | D12: Al Khobar | E12: North Khobar (Prince Saud Al Faisal Rd) | J12: Luxury Residential Compound | K12: Residential compound | L12: Operating (listed) | O12: Villas, townhouses, duplexes (furnished) | Q12: https://www.grandvillage.com.sa/ | S12: +966551222424 | U12: info@grandvillage.com.sa | AC12: Unknown | AE12: Cross-Checked | AF12: Property management, Marketing & leasing, Social media management | AG12: 0 | AH12: 8 | AI12: 12 | AJ12: 15 | AK12: 0 | AL12: 0 | AM12: =SUM(AG12:AL12) -> 35 | AN12: =IF(AM12>=80,"A",IF(AM12>=60,"B","C")) -> C | AP12: https://www.propertyfinder.sa/blog/%D9%83%D9%85%D8%A8%D9%88%D9%86%D8%AF%D8%A7%D8%AA-%D8%A7%D9%84%D8%AE%D8%A8%D8%B1-%D9%85%D8%AC%D9%85%D8%B9%D8%A7%D8%AA-%D8%B3%D9%83%D9%86%D9%8A%D8%A9-%D8%B9%D8%A7%D9%84%D9%85%D9%8A%D8%A9-%D8%B9%D9%84/ ; https://www.grandvillage.com.sa/ | AQ12: 2026-10-11
A13: KHB-012 | B13: Alef Compound | D13: Al Khobar | E13: Ishbiliya / Aziziyah | F13: Ishbilia district, Aziziah | G13: Open map | H13: 26.200387 | I13: 50.215008 | J13: Villa Compound | K13: Residential compound | L13: Operating (listed) | P13: Gym Swimming Pool Kindergarten Reserved Parking Baby Nursery Restaurant Snack Bar Billiard Tables Wireless Internet Satellite Cable Recreational Room Table Tennis Bus Transportation Garbage Chute Children Playground Pest Control Security 24/7 Laundry | Q13: https://alef-home.com/ | U13: info@alef-home.com | V13: https://www.instagram.com/alefkhobar | W13: https://www.facebook.com/Alef-Home-Compound-Khobar-Saudi-Arabia-105496395332383 | Y13: https://twitter.com/AlefHome | AC13: Unknown | AE13: Verified | AF13: Property management, Marketing & leasing, Paid ad campaigns | AG13: 0 | AH13: 8 | AI13: 6 | AJ13: 10 | AK13: 0 | AL13: 5 | AM13: =SUM(AG13:AL13) -> 29 | AN13: =IF(AM13>=80,"A",IF(AM13>=60,"B","C")) -> C | AP13: https://rightcompound.com/compounds/khobar/alef-compound ; https://www.expat.com/en/forum/middle-east/saudi-arabia/khobar/778968-list-of-some-compounds-in-al-khobar-ksa.html ; https://alef-home.com/ | AQ13: 2026-10-11
A14: KHB-013 | B14: Al Ansari Compound One | D14: Al Khobar | F14: Al Khobar | G14: Open map | H14: 26.338191 | I14: 50.179667 | J14: Mixed Residential Compound | K14: Residential compound | L14: Operating (listed) | P14: Gym Swimming Pool Kindergarten Reserved Parking Baby Nursery Billiard Tables Squash Court Basketball Court Volleyball Court Wireless Internet Tennis Court Satellite Cable Recreational Room Bus Transportation Garbage Chute Children Playground Pest Con | Q14: https://alansari.com.sa/ | R14: +966138098913 | S14: +966531223352 | U14: info@alansari.com | X14: https://www.linkedin.com/company/al-ansari-holding-group | Z14: Al Ansari Holding Group (name association) | AB14: Abyan Real Estate Company | AC14: Third-Party Property Management | AD14: https://rightcompound.com/compounds/khobar/al-ansary-compound | AE14: Unverified | AF14: Marketing & leasing, Paid ad campaigns | AG14: 0 | AH14: 8 | AI14: 6 | AJ14: 5 | AK14: 10 | AL14: 5 | AM14: =SUM(AG14:AL14) -> 34 | AN14: =IF(AM14>=80,"A",IF(AM14>=60,"B","C")) -> C | AO14: Owner link to Al Ansari Holding inferred from WhichSchoolAdvisor linking alansari.com.sa; not confirmed. | AP14: https://rightcompound.com/compounds/khobar/al-ansary-compound ; https://www.expat.com/en/forum/middle-east/saudi-arabia/khobar/778968-list-of-some-compounds-in-al-khobar-ksa.html ; https://alansari.com.sa/contact-us/ | AQ14: 2026-10-11
A15: KHB-014 | B15: Al Ansari Compound Two | D15: Al Khobar | E15: Beside French School of Khobar | F15: Al Khobar, beside the French school of Khobar | G15: Open map | H15: 26.324749 | I15: 50.192349 | J15: Mixed Residential Compound | K15: Residential compound | L15: Operating (listed) | N15: 86 | O15: 1-3 bed apartments, 3-bed villas | P15: Gym Swimming Pool Kindergarten Reserved Parking Snack Bar Billiard Tables Squash Court Basketball Court Volleyball Court Wireless Internet Tennis Court Satellite Cable Recreational Room Business Centre Table Tennis Bus Transportation Garbage Chute Ch | Q15: https://alansari.com.sa/ | S15: +966531223352 | AB15: Abyan Real Estate Company | AC15: Third-Party Property Management | AD15: https://rightcompound.com/compounds/khobar/al-ansari-compound-two-al-khobar | AE15: Unverified | AF15: Marketing & leasing, Social media management | AG15: 10 | AH15: 8 | AI15: 12 | AJ15: 5 | AK15: 10 | AL15: 5 | AM15: =SUM(AG15:AL15) -> 50 | AN15: =IF(AM15>=80,"A",IF(AM15>=60,"B","C")) -> C | AP15: https://rightcompound.com/compounds/khobar/al-ansari-compound-two-al-khobar ; https://whichschooladvisor.com/saudi/area-guide/eastern-province/al-khobar | AQ15: 2026-10-11
A16: KHB-015 | B16: Black Pearl Residential Compound | C16: مجمع اللؤلؤة السوداء (بلاك بيرل) | D16: Al Khobar | E16: Al Aziziyah | F16: Azzizyah | G16: Open map | H16: 26.205285 | I16: 50.181047 | J16: Luxury Residential Compound | K16: Residential compound | L16: Operating (listed) | N16: 138 | O16: VIP villas 272 sqm, villas 232 sqm, apartments 107 sqm | P16: Gym Swimming Pool Kindergarten Restaurant Billiard Tables Squash Court Basketball Court Volleyball Court Wireless Internet Tennis Court Satellite Cable Recreational Room Table Tennis Bus Transportation Children Playground Pest Control Security 24/7 M | Q16: https://www.aswadgroup.com/info/al-aswad-compound | R16: +966138055050 | S16: +966503105813 | U16: info@aswadgroup.com | Z16: Aswad Group (Al Aswad Compound) | AC16: Owner Managed | AD16: https://www.aswadgroup.com/info/al-aswad-compound | AE16: Verified | AF16: Property management, Marketing & leasing, Social media management | AG16: 15 | AH16: 8 | AI16: 12 | AJ16: 15 | AK16: 10 | AL16: 5 | AM16: =SUM(AG16:AL16) -> 65 | AN16: =IF(AM16>=80,"A",IF(AM16>=60,"B","C")) -> B | AP16: https://rightcompound.com/compounds/khobar/black-pearl-residential-compound ; https://whichschooladvisor.com/saudi/area-guide/eastern-province/al-khobar ; https://www.propertyfinder.sa/blog/%D9%83%D9%85%D8%A8%D9%88%D9%86%D8%AF%D8%A7%D8%AA-%D8%A7%D9%84%D8%AE%D8%A8%D8%B1-%D9%85%D8%AC%D9%85%D8%B9%D8%A7%D8%AA-%D8%B3%D9%83%D9%86%D9%8A%D8%A9-%D8%B9%D8%A7%D9%84%D9%85%D9%8A%D8%A9-%D8%B9%D9%84/ ; https://www.aswadgroup.com/info/al-aswad-compound | AQ16: 2026-10-11
A17: KHB-016 | B17: Jzala Residential Compound | C17: كمبوند جزالا | D17: Al Khobar | E17: King Saud St (Old Airport Rd) | F17: King Saud St | G17: Open map | H17: 26.335634 | I17: 50.17971 | J17: Villa Compound | K17: Residential compound | L17: Operating (listed) | N17: 100 | O17: Villas 240/260 sqm | P17: Gym Swimming Pool Reserved Parking Baby Nursery Library Restaurant Ballroom Snack Bar Squash Court Basketball Court Volleyball Court Wireless Internet Tennis Court Satellite Cable Recreational Room Business Centre Table Tennis Bus Transportation | S17: 0507328261 | U17: j1@jzala.net | AC17: Unknown | AE17: Cross-Checked | AF17: Property management, Marketing & leasing, Social media management, Content & photography, Integrated services | AG17: 15 | AH17: 8 | AI17: 20 | AJ17: 15 | AK17: 0 | AL17: 5 | AM17: =SUM(AG17:AL17) -> 63 | AN17: =IF(AM17>=80,"A",IF(AM17>=60,"B","C")) -> B | AO17: 'More than 100 villas' (Property Finder). | AP17: https://rightcompound.com/compounds/khobar/jzala-residential-compound-i ; https://www.expat.com/en/forum/middle-east/saudi-arabia/khobar/778968-list-of-some-compounds-in-al-khobar-ksa.html ; https://www.propertyfinder.sa/blog/%D9%83%D9%85%D8%A8%D9%88%D9%86%D8%AF%D8%A7%D8%AA-%D8%A7%D9%84%D8%AE%D8%A8%D8%B1-%D9%85%D8%AC%D9%85%D8%B9%D8%A7%D8%AA-%D8%B3%D9%83%D9%86%D9%8A%D8%A9-%D8%B9%D8%A7%D9%84%D9%85%D9%8A%D8%A9-%D8%B9%D9%84/ | AQ17: 2026-10-11
A18: KHB-017 | B18: Al Fares Residential Compound | C18: مجمع الفارس السكني | D18: Al Khobar | E18: Al Manara Al Bayda St (near Corniche) | F18: 7292 Al Manarah Al Bayda | G18: Open map | H18: 26.327196 | I18: 50.225152 | J18: Villa Compound | K18: Residential compound | L18: Operating (listed) | N18: 15 | O18: 4-bed villas 240 sqm | P18: Gym Swimming Pool Reserved Parking Ballroom Billiard Tables Wireless Internet Satellite Cable Table Tennis Children Playground Pest Control Security 24/7 Maintenance Barbecue Area Outdoor Children Playground Multipurpose Hall Shaded Parking Area Saun | S18: 0500733111 | U18: kazlak@alworoud.com | AC18: Unknown | AE18: Unverified | AF18: Property management, Marketing & leasing, Social media management, Content & photography, Integrated services | AG18: 5 | AH18: 8 | AI18: 20 | AJ18: 5 | AK18: 0 | AL18: 5 | AM18: =SUM(AG18:AL18) -> 43 | AN18: =IF(AM18>=80,"A",IF(AM18>=60,"B","C")) -> C | AO18: 15 villas (Property Finder) vs 16 (RightCompound). | AP18: https://rightcompound.com/compounds/khobar/alfares-compound ; https://www.propertyfinder.sa/blog/%D9%83%D9%85%D8%A8%D9%88%D9%86%D8%AF%D8%A7%D8%AA-%D8%A7%D9%84%D8%AE%D8%A8%D8%B1-%D9%85%D8%AC%D9%85%D8%B9%D8%A7%D8%AA-%D8%B3%D9%83%D9%86%D9%8A%D8%A9-%D8%B9%D8%A7%D9%84%D9%85%D9%8A%D8%A9-%D8%B9%D9%84/ | AQ18: 2026-10-11
A19: KHB-018 | B19: Al Remal Village | C19: مجمع الرمال السكني | D19: Al Khobar | E19: Al Andalus / Golden Belt (Al Quds St) | J19: Mixed Residential Compound | K19: Residential compound | L19: Unknown | N19: 124 | O19: Villas, duplexes, townhouses, 1-2 bed apartments | R19: 920004598 | S19: 0508146999 | AC19: Unknown | AE19: Unverified | AF19: Property management, Marketing & leasing, Social media management, Content & photography, Integrated services | AG19: 15 | AH19: 8 | AI19: 20 | AJ19: 5 | AK19: 0 | AL19: 0 | AM19: =SUM(AG19:AL19) -> 48 | AN19: =IF(AM19>=80,"A",IF(AM19>=60,"B","C")) -> C | AP19: https://whichschooladvisor.com/saudi/area-guide/eastern-province/al-khobar ; https://www.propertyfinder.sa/blog/%D9%83%D9%85%D8%A8%D9%88%D9%86%D8%AF%D8%A7%D8%AA-%D8%A7%D9%84%D8%AE%D8%A8%D8%B1-%D9%85%D8%AC%D9%85%D8%B9%D8%A7%D8%AA-%D8%B3%D9%83%D9%86%D9%8A%D8%A9-%D8%B9%D8%A7%D9%84%D9%85%D9%8A%D8%A9-%D8%B9%D9%84/ | AQ19: 2026-10-11
A20: KHB-019 | B20: Nesma Compound | C20: كمباوند نسمة | D20: Al Khobar | E20: Al Jawhara (Al Quds St) | J20: Villa Compound | K20: Residential compound | L20: Unknown | O20: Villas | R20: +966138871838 | S20: 0535553932 | X20: https://www.linkedin.com/company/nesma-holding | Z20: Nesma Real Estate Company (per Property Finder) | AC20: Owner Managed | AD20: https://www.propertyfinder.sa/blog/%D9%83%D9%85%D8%A8%D9%88%D9%86%D8%AF%D8%A7%D8%AA-%D8%A7%D9%84%D8%AE%D8%A8%D8%B1-%D9%85%D8%AC%D9%85%D8%B9%D8%A7%D8%AA-%D8%B3%D9%83%D9%86%D9%8A%D8%A9-%D8%B9%D8%A7%D9%84%D9%85%D9%8A%D8%A9-%D8%B9%D9%84/ | AE20: Unverified | AF20: Property management, Marketing & leasing, Content & photography, Paid ad campaigns, Integrated services | AG20: 0 | AH20: 8 | AI20: 14 | AJ20: 5 | AK20: 10 | AL20: 0 | AM20: =SUM(AG20:AL20) -> 37 | AN20: =IF(AM20>=80,"A",IF(AM20>=60,"B","C")) -> C | AP20: https://www.propertyfinder.sa/blog/%D9%83%D9%85%D8%A8%D9%88%D9%86%D8%AF%D8%A7%D8%AA-%D8%A7%D9%84%D8%AE%D8%A8%D8%B1-%D9%85%D8%AC%D9%85%D8%B9%D8%A7%D8%AA-%D8%B3%D9%83%D9%86%D9%8A%D8%A9-%D8%B9%D8%A7%D9%84%D9%85%D9%8A%D8%A9-%D8%B9%D9%84/ | AQ20: 2026-10-11
A21: KHB-020 | B21: Qurtuba Residential Complex | C21: مجمع قرطبة السكني | D21: Al Khobar | E21: Qurtubah (Prince Sultan Rd) | J21: Apartment Compound | K21: Residential compound | L21: Unknown | N21: 46 | O21: Furnished studios, 1-2 bed apartments | AC21: Unknown | AE21: Not Available | AF21: Property management, Marketing & leasing, Social media management, Content & photography, Integrated services | AG21: 5 | AH21: 8 | AI21: 20 | AJ21: 0 | AK21: 0 | AL21: 0 | AM21: =SUM(AG21:AL21) -> 33 | AN21: =IF(AM21>=80,"A",IF(AM21>=60,"B","C")) -> C | AP21: https://www.propertyfinder.sa/blog/%D9%83%D9%85%D8%A8%D9%88%D9%86%D8%AF%D8%A7%D8%AA-%D8%A7%D9%84%D8%AE%D8%A8%D8%B1-%D9%85%D8%AC%D9%85%D8%B9%D8%A7%D8%AA-%D8%B3%D9%83%D9%86%D9%8A%D8%A9-%D8%B9%D8%A7%D9%84%D9%85%D9%8A%D8%A9-%D8%B9%D9%84/ | AQ21: 2026-10-11
A22: KHB-021 | B22: Retal Khobar (Rtal Square) | C22: كمباوند رتال الخبر | D22: Al Khobar | E22: Al Bandariyah | J22: Apartment Compound | K22: Residential compound | L22: Unknown | N22: 96 | O22: 2-4 bed apartments (for sale) | R22: +966920021022 | AA22: Retal (per Property Finder) | AC22: Developer Managed | AE22: Unverified | AF22: Marketing & leasing, Social media management, Content & photography | AG22: 10 | AH22: 8 | AI22: 20 | AJ22: 5 | AK22: 5 | AL22: 0 | AM22: =SUM(AG22:AL22) -> 48 | AN22: =IF(AM22>=80,"A",IF(AM22>=60,"B","C")) -> C | AO22: Sale project, not rental compound. | AP22: https://www.propertyfinder.sa/blog/%D9%83%D9%85%D8%A8%D9%88%D9%86%D8%AF%D8%A7%D8%AA-%D8%A7%D9%84%D8%AE%D8%A8%D8%B1-%D9%85%D8%AC%D9%85%D8%B9%D8%A7%D8%AA-%D8%B3%D9%83%D9%86%D9%8A%D8%A9-%D8%B9%D8%A7%D9%84%D9%85%D9%8A%D8%A9-%D8%B9%D9%84/ | AQ22: 2026-10-11
A23: KHB-022 | B23: Seashore Residence | C23: كومباوند سي شور | D23: Al Khobar | F23: Aziziyah district | G23: Open map | H23: 26.16613 | I23: 50.195653 | J23: Mixed Residential Compound | K23: Residential compound | L23: Operating (listed) | O23: Villas 201-210 sqm, apartments 43-48 sqm | P23: Gym Swimming Pool Kindergarten Reserved Parking Baby Nursery Library Restaurant Billiard Tables Basketball Court Volleyball Court Wireless Internet Tennis Court Satellite Cable Recreational Room Business Centre Table Tennis Bus Transportation Cinema | Q23: https://seashoreresidence.com/ | S23: 0567700021 | AC23: Unknown | AE23: Unverified | AF23: Property management, Marketing & leasing, Social media management | AG23: 0 | AH23: 8 | AI23: 12 | AJ23: 5 | AK23: 0 | AL23: 5 | AM23: =SUM(AG23:AL23) -> 30 | AN23: =IF(AM23>=80,"A",IF(AM23>=60,"B","C")) -> C | AO23: WhatsApp link on site points to a +30 (Greece) number - treated as template error, not stored. | AP23: https://rightcompound.com/compounds/khobar/sea-shore-compound ; https://www.expat.com/en/forum/middle-east/saudi-arabia/khobar/778968-list-of-some-compounds-in-al-khobar-ksa.html ; https://www.propertyfinder.sa/blog/%D9%83%D9%85%D8%A8%D9%88%D9%86%D8%AF%D8%A7%D8%AA-%D8%A7%D9%84%D8%AE%D8%A8%D8%B1-%D9%85%D8%AC%D9%85%D8%B9%D8%A7%D8%AA-%D8%B3%D9%83%D9%86%D9%8A%D8%A9-%D8%B9%D8%A7%D9%84%D9%85%D9%8A%D8%A9-%D8%B9%D9%84/ | AQ23: 2026-10-11
A24: KHB-023 | B24: Saraya Al Olaya Towers | D24: Al Khobar | F24: Olaya district facing Dhahran Mall | G24: Open map | H24: 26.300642 | I24: 50.171363 | J24: Apartment Compound | K24: Residential compound | L24: Operating (listed) | P24: Gym Swimming Pool Kindergarten Reserved Parking Baby Nursery Beauty Salon Satellite Cable Recreational Room Garbage Chute Children Playground Pest Control Security 24/7 Laundry Service Maintenance Outdoor Children Playground Lounge Multipurpose Hall | Q24: https://www.darwaemaar.com/ | R24: 920004077 | T24: 920004077 | AA24: Dar Wa Emaar Real Estate | AB24: Dar Wa Emaar Real Estate | AC24: Developer Managed | AD24: https://rightcompound.com/compounds/khobar/saraya-al-olaya-residential-tower | AE24: Verified | AF24: Marketing & leasing, Social media management | AG24: 0 | AH24: 8 | AI24: 12 | AJ24: 10 | AK24: 10 | AL24: 5 | AM24: =SUM(AG24:AL24) -> 45 | AN24: =IF(AM24>=80,"A",IF(AM24>=60,"B","C")) -> C | AP24: https://rightcompound.com/compounds/khobar/saraya-al-olaya-residential-tower ; https://www.darwaemaar.com/ | AQ24: 2026-10-11
A25: KHB-024 | B25: Saraya Al Rawabi Complex | D25: Al Khobar | F25: Rawabi district adjacent to Hyper Panda and Extra Stores Khobar | G25: Open map | H25: 26.327012 | I25: 50.212315 | J25: Apartment Compound | K25: Residential compound | L25: Operating (listed) | N25: 66 | P25: Swimming Pool Reserved Parking Garbage Chute Pest Control Security 24/7 Maintenance Outdoor Children Playground Shaded Parking Area | Q25: https://www.darwaemaar.com/ | R25: 920004077 | T25: 920004077 | AA25: Dar Wa Emaar Real Estate | AB25: Dar Wa Emaar Real Estate | AC25: Developer Managed | AD25: https://rightcompound.com/compounds/khobar/saraya-al-rawabi-complex | AE25: Verified | AF25: Marketing & leasing, Social media management | AG25: 10 | AH25: 8 | AI25: 12 | AJ25: 10 | AK25: 10 | AL25: 5 | AM25: =SUM(AG25:AL25) -> 55 | AN25: =IF(AM25>=80,"A",IF(AM25>=60,"B","C")) -> C | AP25: https://rightcompound.com/compounds/khobar/saraya-al-rawabi-complex ; https://www.darwaemaar.com/ | AQ25: 2026-10-11
A26: KHB-025 | B26: Refad Compound | D26: Al Khobar | F26: Prince Faisal Bin Fahad Road | G26: Open map | H26: 26.304615 | I26: 50.191496 | J26: Mixed Residential Compound | K26: Residential compound | L26: Operating (listed) | N26: 100 | O26: Villas, apartments, duplexes | P26: Gym Reserved Parking Basketball Court Wireless Internet Satellite Cable Recreational Room Bus Transportation Children Playground Pest Control Security 24/7 Laundry Service Maintenance Outdoor Children Playground Mini Market Multipurpose Hall Green Ar | Q26: https://refadcompound.com/ | R26: +966920031839 | AC26: Unknown | AE26: Unverified | AF26: Property management, Marketing & leasing, Social media management | AG26: 15 | AH26: 8 | AI26: 12 | AJ26: 5 | AK26: 0 | AL26: 5 | AM26: =SUM(AG26:AL26) -> 45 | AN26: =IF(AM26>=80,"A",IF(AM26>=60,"B","C")) -> C | AO26: Official site renders no contact data. | AP26: https://rightcompound.com/compounds/khobar/refad-compound ; https://whichschooladvisor.com/saudi/area-guide/eastern-province/al-khobar ; https://compoundin.com/compounds/khobar/refad-compound | AQ26: 2026-10-11
A27: KHB-026 | B27: Palm Springs Compound | D27: Al Khobar | E27: Al Qishla (behind Abdulla Fouad Tower) | F27: Al Qishla area , behind Abdulla Fouad Tower | G27: Open map | H27: 26.371657 | I27: 50.170419 | J27: Mixed Residential Compound | K27: Residential compound | L27: Operating (listed) | N27: 129 | O27: 2-bed apartments, 3-bed villas | P27: Gym Swimming Pool Kindergarten Reserved Parking Baby Nursery Library Beauty Salon Restaurant Snack Bar Billiard Tables Basketball Court Volleyball Court Wireless Internet Tennis Court Satellite Cable Pre-school Centre Recreational Room Bowling Table | S27: +966505872304 | Z27: Abdulla Fouad Holding Company | AC27: Owner Managed | AD27: https://rightcompound.com/compounds/khobar/palm-springs-compound | AE27: Unverified | AF27: Property management, Marketing & leasing, Social media management, Content & photography, Integrated services | AG27: 15 | AH27: 8 | AI27: 20 | AJ27: 5 | AK27: 10 | AL27: 5 | AM27: =SUM(AG27:AL27) -> 63 | AN27: =IF(AM27>=80,"A",IF(AM27>=60,"B","C")) -> B | AP27: https://rightcompound.com/compounds/khobar/palm-springs-compound ; https://www.expat.com/en/forum/middle-east/saudi-arabia/khobar/778968-list-of-some-compounds-in-al-khobar-ksa.html | AQ27: 2026-10-11
A28: KHB-027 | B28: Dana Beach Resort | D28: Al Khobar | E28: Half Moon Bay (Dana Bay) | F28: Dana Bay | G28: Open map | H28: 26.080461 | I28: 49.998589 | J28: Luxury Residential Compound | K28: Residential compound | L28: Operating (listed) | P28: Gym Swimming Pool Reserved Parking Beauty Salon Restaurant Snack Bar Wireless Internet Satellite Cable Recreational Room Business Centre Children Playground Pest Control Security 24/7 Laundry Service Maintenance Barbecue Area Outdoor Children Playgro | S28: +966500501768 | AC28: Unknown | AE28: Unverified | AF28: Property management, Marketing & leasing, Social media management, Content & photography, Integrated services | AG28: 0 | AH28: 8 | AI28: 20 | AJ28: 5 | AK28: 0 | AL28: 5 | AM28: =SUM(AG28:AL28) -> 38 | AN28: =IF(AM28>=80,"A",IF(AM28>=60,"B","C")) -> C | AP28: https://rightcompound.com/compounds/khobar/dana-beach-resort | AQ28: 2026-10-11
A29: KHB-028 | B29: Green Park Lifestyle Residence | D29: Al Khobar | E29: Al Jawhara | F29: Al Jawhara , Al Khobar | G29: Open map | H29: 26.325954 | I29: 50.197316 | J29: Mixed Residential Compound | K29: Residential compound | L29: Operating (listed) | P29: Gym Swimming Pool Reserved Parking Recreational Room Garbage Chute Children Playground Pest Control Security 24/7 Maintenance Outdoor Children Playground Multipurpose Hall Green Area and Shaded Area CCTV Football Court Outdoor Swimming Pool Outdoor G | S29: +966543787979 | AC29: Unknown | AE29: Unverified | AF29: Property management, Marketing & leasing, Social media management, Content & photography, Integrated services | AG29: 0 | AH29: 8 | AI29: 20 | AJ29: 5 | AK29: 0 | AL29: 5 | AM29: =SUM(AG29:AL29) -> 38 | AN29: =IF(AM29>=80,"A",IF(AM29>=60,"B","C")) -> C | AP29: https://rightcompound.com/compounds/khobar/green-park-lifestyle-residence-compound | AQ29: 2026-10-11
A30: KHB-029 | B30: Marissa Elite Complex | D30: Dhahran (Greater Khobar) | E30: Al Qusor | F30: Al-Qusor neighborhood in Dhahran city. | G30: Open map | H30: 26.342522 | I30: 50.151466 | J30: Mixed Residential Compound | K30: Residential compound | L30: Operating (listed) | P30: Gym Reserved Parking Baby Nursery Garbage Chute Children Playground Maintenance Rooftop Garden Barbecue Area Lounge Multipurpose Hall Green Area and Shaded Area CCTV Basement Private Parking Rooftop Barbecue Area | S30: +966553592411 | AC30: Unknown | AE30: Unverified | AF30: Property management, Marketing & leasing, Social media management, Content & photography, Integrated services | AG30: 0 | AH30: 8 | AI30: 20 | AJ30: 5 | AK30: 0 | AL30: 5 | AM30: =SUM(AG30:AL30) -> 38 | AN30: =IF(AM30>=80,"A",IF(AM30>=60,"B","C")) -> C | AP30: https://rightcompound.com/compounds/khobar/marissa-elite-compound-dhahran | AQ30: 2026-10-11
A31: KHB-030 | B31: Le Ruya Residential Resort | D31: Al Khobar | E31: Ishbiliya (Al Bayan St) | F31: Ishbilia District, Al Bayan Street | G31: Open map | H31: 26.19505 | I31: 50.215652 | J31: Family Compound | K31: Residential compound | L31: Operating (listed) | P31: Gym Beauty Salon Billiard Tables Basketball Court Wireless Internet Tennis Court Bowling Bus Transportation Children Playground Pest Control Security 24/7 Maintenance Barbecue Area Outdoor Children Playground Mini Market Gaming Room Cafeteria Green A | S31: 0559318510 | AC31: Unknown | AE31: Unverified | AF31: Property management, Marketing & leasing, Social media management, Content & photography, Integrated services | AG31: 0 | AH31: 8 | AI31: 20 | AJ31: 5 | AK31: 0 | AL31: 5 | AM31: =SUM(AG31:AL31) -> 38 | AN31: =IF(AM31>=80,"A",IF(AM31>=60,"B","C")) -> C | AP31: https://rightcompound.com/compounds/khobar/le-ruya | AQ31: 2026-10-11
A32: KHB-031 | B32: South Park Compound | D32: Dhahran (Greater Khobar) | E32: Al Douha | F32: Al Douha Neighborhood | G32: Open map | H32: 26.320469 | I32: 50.155167 | J32: Mixed Residential Compound | K32: Residential compound | L32: Operating (listed) | P32: Gym Children Playground Pest Control Maintenance Housekeeping Services CCTV Fiber Optic High Speed Internet Terrace | S32: 0538090077 | AC32: Unknown | AE32: Unverified | AF32: Property management, Marketing & leasing, Social media management, Content & photography, Integrated services | AG32: 0 | AH32: 8 | AI32: 20 | AJ32: 5 | AK32: 0 | AL32: 5 | AM32: =SUM(AG32:AL32) -> 38 | AN32: =IF(AM32>=80,"A",IF(AM32>=60,"B","C")) -> C | AP32: https://rightcompound.com/compounds/khobar/south-park-compound | AQ32: 2026-10-11
A33: KHB-032 | B33: Loay Compound | D33: Al Khobar | F33: Al Khobar | G33: Open map | H33: 26.295877 | I33: 50.110016 | J33: Mixed Residential Compound | K33: Residential compound | L33: Operating (listed) | P33: Gym Swimming Pool Basketball Court Table Tennis Bus Transportation | S33: 0554216987 | AC33: Unknown | AE33: Unverified | AF33: Property management, Marketing & leasing, Social media management, Content & photography, Integrated services | AG33: 0 | AH33: 8 | AI33: 20 | AJ33: 5 | AK33: 0 | AL33: 5 | AM33: =SUM(AG33:AL33) -> 38 | AN33: =IF(AM33>=80,"A",IF(AM33>=60,"B","C")) -> C | AO33: RightCompound description is placeholder text; existence needs field check. | AP33: https://rightcompound.com/compounds/khobar/loay-compound | AQ33: 2026-10-11
A34: KHB-033 | B34: Al Riyadh Compound | D34: Al Khobar | F34: KSA | G34: Open map | H34: 26.29103 | I34: 50.211983 | J34: Villa Compound | K34: Residential compound | L34: Operating (listed) | N34: 100 | O34: 3-bed villas | P34: Gym Swimming Pool Reserved Parking Beauty Salon Restaurant Snack Bar Billiard Tables Squash Court Basketball Court Volleyball Court Wireless Internet Tennis Court Satellite Cable Recreational Room Business Centre Bowling Table Tennis Bus Transportati | Z34: Arabian Property Services (APS) | AC34: Owner Managed | AD34: https://rightcompound.com/compounds/khobar/al-riyadh-compound | AE34: Not Available | AF34: Property management, Marketing & leasing, Social media management, Content & photography, Integrated services | AG34: 15 | AH34: 8 | AI34: 20 | AJ34: 0 | AK34: 10 | AL34: 5 | AM34: =SUM(AG34:AL34) -> 58 | AN34: =IF(AM34>=80,"A",IF(AM34>=60,"B","C")) -> C | AP34: https://rightcompound.com/compounds/khobar/al-riyadh-compound ; https://www.expat.com/en/forum/middle-east/saudi-arabia/khobar/778968-list-of-some-compounds-in-al-khobar-ksa.html | AQ34: 2026-10-11
A35: KHB-034 | B35: Al Safa Homes (Al Saeed Village 5) | D35: Al Khobar | E35: Al Rakah | F35: KSA | J35: Villa Compound | K35: Residential compound | L35: Operating (listed) | N35: 32 | P35: Gym Swimming Pool Reserved Parking Baby Nursery Beauty Salon Restaurant Billiard Tables Basketball Court Volleyball Court Wireless Internet Tennis Court Satellite Cable Recreational Room Bus Transportation | AB35: Mazen Al Saeed Group | AC35: Owner Managed | AD35: https://rightcompound.com/compounds/khobar/al-safa-homes-compound | AE35: Not Available | AF35: Property management, Marketing & leasing, Social media management, Content & photography, Integrated services | AG35: 5 | AH35: 8 | AI35: 20 | AJ35: 0 | AK35: 10 | AL35: 5 | AM35: =SUM(AG35:AL35) -> 48 | AN35: =IF(AM35>=80,"A",IF(AM35>=60,"B","C")) -> C | AP35: https://rightcompound.com/compounds/khobar/al-safa-homes-compound | AQ35: 2026-10-11
A36: KHB-035 | B36: Al Sharq Homes (Al Saeed Village 3) | D36: Al Khobar | F36: KSA | G36: Open map | H36: 26.367418 | I36: 50.203571 | J36: Luxury Residential Compound | K36: Residential compound | L36: Operating (listed) | P36: Gym Swimming Pool Reserved Parking Baby Nursery Beauty Salon Restaurant Billiard Tables Basketball Court Volleyball Court Wireless Internet Tennis Court Satellite Cable Recreational Room Table Tennis Bus Transportation | AB36: Mazen Al Saeed Group | AC36: Owner Managed | AD36: https://rightcompound.com/compounds/khobar/al-sharq-homes-compound | AE36: Not Available | AF36: Property management, Marketing & leasing, Social media management, Content & photography, Integrated services | AG36: 0 | AH36: 8 | AI36: 20 | AJ36: 0 | AK36: 10 | AL36: 5 | AM36: =SUM(AG36:AL36) -> 43 | AN36: =IF(AM36>=80,"A",IF(AM36>=60,"B","C")) -> C | AP36: https://rightcompound.com/compounds/khobar/al-sharq-homes-compound | AQ36: 2026-10-11
A37: KHB-036 | B37: Al Yasmeen Homes (Al Saeed Village 4) | D37: Al Khobar | F37: KSA | G37: Open map | H37: 26.367033 | I37: 50.204258 | J37: Apartment Compound | K37: Residential compound | L37: Operating (listed) | N37: 40 | O37: Furnished apartments | P37: Gym Swimming Pool Reserved Parking Baby Nursery Beauty Salon Restaurant Billiard Tables Basketball Court Volleyball Court Wireless Internet Tennis Court Satellite Cable Recreational Room Table Tennis Bus Transportation | AB37: Mazen Al Saeed Group | AC37: Owner Managed | AD37: https://rightcompound.com/compounds/khobar/al-yasmeen-homes-compound | AE37: Not Available | AF37: Property management, Marketing & leasing, Social media management, Content & photography, Integrated services | AG37: 5 | AH37: 8 | AI37: 20 | AJ37: 0 | AK37: 10 | AL37: 5 | AM37: =SUM(AG37:AL37) -> 48 | AN37: =IF(AM37>=80,"A",IF(AM37>=60,"B","C")) -> C | AP37: https://rightcompound.com/compounds/khobar/al-yasmeen-homes-compound | AQ37: 2026-10-11
A38: KHB-037 | B38: Saeed Residential Compound 1 | D38: Al Khobar | F38: KSA | G38: Open map | H38: 26.367879 | I38: 50.20752 | J38: Villa Compound | K38: Residential compound | L38: Operating (listed) | N38: 30 | P38: Gym Swimming Pool Reserved Parking Baby Nursery Billiard Tables Basketball Court Volleyball Court Tennis Court Recreational Room | AC38: Unknown | AE38: Not Available | AF38: Property management, Marketing & leasing, Social media management, Content & photography, Integrated services | AG38: 5 | AH38: 8 | AI38: 20 | AJ38: 0 | AK38: 0 | AL38: 5 | AM38: =SUM(AG38:AL38) -> 38 | AN38: =IF(AM38>=80,"A",IF(AM38>=60,"B","C")) -> C | AO38: Possibly part of Mazen Al Saeed Group villages; not confirmed. | AP38: https://rightcompound.com/compounds/khobar/saeed-residential-compound-1 | AQ38: 2026-10-11
A39: KHB-038 | B39: Al Shablan Compounds | D39: Al Khobar | F39: KSA | G39: Open map | H39: 26.336807 | I39: 50.215416 | J39: Mixed Residential Compound | K39: Residential compound | L39: Operating (listed) | P39: Gym Swimming Pool Reserved Parking Bus Transportation | Z39: Al Shablan Group | AC39: Owner Managed | AD39: https://rightcompound.com/compounds/khobar/al-shablan-compounds | AE39: Not Available | AF39: Property management, Marketing & leasing, Social media management, Content & photography, Integrated services | AG39: 0 | AH39: 8 | AI39: 20 | AJ39: 0 | AK39: 10 | AL39: 5 | AM39: =SUM(AG39:AL39) -> 43 | AN39: =IF(AM39>=80,"A",IF(AM39>=60,"B","C")) -> C | AO39: Group manages five compounds (four in Eastern Province); individual compounds not itemised. | AP39: https://rightcompound.com/compounds/khobar/al-shablan-compounds | AQ39: 2026-10-11
A40: KHB-039 | B40: Opal Compound | D40: Al Khobar | F40: Al Khobar | G40: Open map | H40: 26.362605 | I40: 50.204311 | J40: Mixed Residential Compound | K40: Residential compound | L40: Operating (listed) | O40: 3-bed villas 110 sqm, studios 65 sqm | P40: Reserved Parking Recreational Room Children Playground Outdoor Children Playground Multipurpose Hall Green Area and Shaded Area | AB40: AZ Real Estate Management | AC40: Third-Party Property Management | AD40: https://rightcompound.com/compounds/khobar/opal-compound | AE40: Not Available | AF40: Marketing & leasing, Social media management, Content & photography | AG40: 0 | AH40: 8 | AI40: 20 | AJ40: 0 | AK40: 10 | AL40: 5 | AM40: =SUM(AG40:AL40) -> 43 | AN40: =IF(AM40>=80,"A",IF(AM40>=60,"B","C")) -> C | AP40: https://rightcompound.com/compounds/khobar/opal-compound | AQ40: 2026-10-11
...

Sheet Al Khobar
A1: ID | B1: Compound (EN) | C1: Compound (AR) | D1: City | E1: District | F1: Address | G1: Google Maps | H1: Latitude | I1: Longitude | J1: Compound Type | K1: Category | L1: Status | M1: Opened | N1: Units | O1: Unit Types | P1: Facilities | Q1: Website | R1: Main Phone | S1: Mobile | T1: WhatsApp | U1: Emails | V1: Instagram | W1: Facebook | X1: LinkedIn | Y1: Other Social | Z1: Owner | AA1: Developer | AB1: Property Manager / Operator | AC1: Management Type | AD1: Ownership Source | AE1: Contact Verification | AF1: Opportunities | AG1: Size (20) | AH1: Fit (25) | AI1: Need (20) | AJ1: Contact (15) | AK1: Party (10) | AL1: Collab (10) | AM1: Lead Score | AN1: Priority | AO1: Notes | AP1: Sources | AQ1: Last Checked
A2: KHB-001 | B2: Canary Village | D2: Al Khobar | F2: KSA | G2: Open map | H2: 26.349239 | I2: 50.186673 | J2: Villa Compound | K2: Residential compound | L2: Operating (listed) | N2: 159 | O2: Furnished 3-bed villas | P2: Gym Swimming Pool Reserved Parking Baby Nursery Beauty Salon Restaurant Ballroom Billiard Tables Squash Court Basketball Court Volleyball Court Wireless Internet Tennis Court Satellite Cable Pre-school Centre Recreational Room Table Tennis Bus Transp | Q2: https://www.canaryvillage.com/ | R2: +966138590895 | S2: +966534022218 | U2: leasing@canaryvillage.com ; rental.office@canaryvillage.com | V2: https://www.instagram.com/canaryvillage | W2: https://www.facebook.com/canary.canary.714 | Y2: https://twitter.com/canaryvillage | Z2: Rashed Al Rashed & Sons Group | AC2: Owner Managed | AD2: https://rightcompound.com/compounds/khobar/canary-village | AE2: Verified | AF2: Property management, Marketing & leasing, Paid ad campaigns | AG2: 15 | AH2: 8 | AI2: 6 | AJ2: 15 | AK2: 10 | AL2: 5 | AM2: =SUM(AG2:AL2) -> 59 | AN2: =IF(AM2>=80,"A",IF(AM2>=60,"B","C")) -> C | AP2: https://rightcompound.com/compounds/khobar/canary-village ; https://whichschooladvisor.com/saudi/area-guide/eastern-province/al-khobar ; https://www.expat.com/en/forum/middle-east/saudi-arabia/khobar/778968-list-of-some-compounds-in-al-khobar-ksa.html ; https://www.canaryvillage.com/ | AQ2: 2026-10-11
A3: KHB-002 | B3: Canary Vista | D3: Al Khobar | E3: Al Maha / Al Aziziyah | J3: Villa Compound | K3: Residential compound | L3: Operating (listed) | N3: 326 | O3: Villas | Q3: https://canary-vista.com/ | R3: +966138494999 | S3: +966534022276 | U3: rentaloffice@canaryvista.com | V3: https://instagram.com/canaryvistacommunity | W3: https://www.facebook.com/2070283359669619 | AC3: Unknown | AE3: Verified | AF3: Property management, Marketing & leasing, Paid ad campaigns | AG3: 20 | AH3: 8 | AI3: 6 | AJ3: 15 | AK3: 0 | AL3: 0 | AM3: =SUM(AG3:AL3) -> 49 | AN3: =IF(AM3>=80,"A",IF(AM3>=60,"B","C")) -> C | AO3: Former owner Qatif Concessions Management Co. (ExxonMobil) until 2007 per WhichSchoolAdvisor; current owner not confirmed. Same 013 849 4999 number also appears on a Dhahran Tower Beach listing. | AP3: https://whichschooladvisor.com/saudi/area-guide/eastern-province/al-khobar ; https://compoundin.com/compounds/khobar/canary-vista ; https://canary-vista.com/ | AQ3: 2026-10-11
A4: KHB-003 | B4: Eurovillage | D4: Al Khobar | E4: Prince Sultan Road (central Khobar) | J4: Villa Compound | K4: Residential compound | L4: Operating (listed) | N4: 560 | O4: Villas | Q4: https://www.eurovillage.sa/ | R4: 0138579780 | V4: https://www.instagram.com/eurovillage_compound | W4: https://www.facebook.com/EuroVillageSA | X4: https://www.linkedin.com/company/eurovillage-compound | AC4: Unknown | AE4: Verified | AF4: Property management, Paid ad campaigns | AG4: 20 | AH4: 8 | AI4: 0 | AJ4: 10 | AK4: 0 | AL4: 0 | AM4: =SUM(AG4:AL4) -> 38 | AN4: =IF(AM4>=80,"A",IF(AM4>=60,"B","C")) -> C | AO4: 'Over 560 villas' per expat guides; unit count not stated on official site. | AP4: https://soulofsaudi.com/best-compounds-in-saudi-arabia-for-expats/ ; https://www.expat.com/en/forum/middle-east/saudi-arabia/khobar/778968-list-of-some-compounds-in-al-khobar-ksa.html ; https://www.eurovillage.sa/contact/ | AQ4: 2026-10-11
A5: KHB-004 | B5: Las Dunas Compound | D5: Al Khobar | E5: Ar Rawabi | J5: Villa Compound | K5: Residential compound | L5: Operating (listed) | Q5: https://www.lasdunas-sa.com/ | S5: +966505876327 | U5: info@lasdunas-sa.com | AC5: Unknown | AE5: Verified | AF5: Property management, Marketing & leasing, Social media management | AG5: 0 | AH5: 8 | AI5: 6 | AJ5: 15 | AK5: 0 | AL5: 0 | AM5: =SUM(AG5:AL5) -> 29 | AN5: =IF(AM5>=80,"A",IF(AM5>=60,"B","C")) -> C | AP5: https://whichschooladvisor.com/saudi/area-guide/eastern-province/al-khobar ; https://www.lasdunas-sa.com/ | AQ5: 2026-10-11
A6: KHB-005 | B6: Riviera Waterfront Village | C6: ريفييرا قرية الواجهة البحرية | D6: Al Khobar | E6: Ishbiliya | F6: Ishbiliya, Al Khobar 34712 | G6: Open map | H6: 26.200206 | I6: 50.216558 | J6: Luxury Residential Compound | K6: Residential compound | L6: Operating (listed) | O6: Studios, 1-3 bed apartments, villas | P6: Gym Swimming Pool Kindergarten Reserved Parking Baby Nursery Beauty Salon Restaurant Ballroom Snack Bar Billiard Tables Squash Court Basketball Court Wireless Internet Tennis Court Satellite Cable Commercial Centre Recreational Room Business Centre T | Q6: https://www.rivieracompound.com/ | R6: 0138193555 | S6: 0580875741 | V6: https://www.instagram.com/rivieracompound | W6: https://www.facebook.com/Rivieracompoundsa | X6: https://www.linkedin.com/showcase/rivieracompound | Y6: https://www.snapchat.com/add/compoundriviera ; https://twitter.com/RivieraCompound | AC6: Unknown | AE6: Verified | AF6: Property management, Marketing & leasing, Paid ad campaigns | AG6: 0 | AH6: 8 | AI6: 6 | AJ6: 10 | AK6: 0 | AL6: 5 | AM6: =SUM(AG6:AL6) -> 29 | AN6: =IF(AM6>=80,"A",IF(AM6>=60,"B","C")) -> C | AP6: https://rightcompound.com/compounds/khobar/riviera-waterfront-village ; https://whichschooladvisor.com/saudi/area-guide/eastern-province/al-khobar ; https://www.rivieracompound.com/ | AQ6: 2026-10-11
A7: KHB-006 | B7: Al Mohamadia Compound | C7: مجمع المحمدية | D7: Al Khobar | E7: Al Sadafah | F7: Al Khobar | G7: Open map | H7: 26.366418 | I7: 50.210438 | J7: Mixed Residential Compound | K7: Residential compound | L7: Operating (listed) | N7: 262 | O7: Villas, apartments, studios | P7: Gym Swimming Pool Reserved Parking Baby Nursery Beauty Salon Restaurant Snack Bar Billiard Tables Basketball Court Volleyball Court Wireless Internet Tennis Court Satellite Cable Recreational Room Table Tennis Bus Transportation | Q7: https://www.al-othman.com/ar/al-mohamadia-compound | R7: +966138142288 | U7: info@al-othman.com | V7: https://instagram.com/alothman.holding | W7: https://www.facebook.com/pages/AlOthman-Holding/1492267767733144 | X7: https://www.linkedin.com/company/al--othman-holding-company | Z7: Al Othman Holding Company | AB7: Al Othman Holding Company | AC7: Owner Managed | AD7: https://rightcompound.com/compounds/khobar/mohamadia-compound | AE7: Verified | AF7: Property management, Marketing & leasing, Paid ad campaigns | AG7: 20 | AH7: 8 | AI7: 6 | AJ7: 15 | AK7: 10 | AL7: 5 | AM7: =SUM(AG7:AL7) -> 64 | AN7: =IF(AM7>=80,"A",IF(AM7>=60,"B","C")) -> B | AO7: Unit count differs: 262 (Property Finder), 96 (RightCompound), 1,152 (WhichSchoolAdvisor). Contacts are the holding company's. | AP7: https://rightcompound.com/compounds/khobar/mohamadia-compound ; https://www.propertyfinder.sa/blog/%D9%83%D9%85%D8%A8%D9%88%D9%86%D8%AF%D8%A7%D8%AA-%D8%A7%D9%84%D8%AE%D8%A8%D8%B1-%D9%85%D8%AC%D9%85%D8%B9%D8%A7%D8%AA-%D8%B3%D9%83%D9%86%D9%8A%D8%A9-%D8%B9%D8%A7%D9%84%D9%85%D9%8A%D8%A9-%D8%B9%D9%84/ ; https://whichschooladvisor.com/saudi/area-guide/eastern-province/al-khobar ; https://www.al-othman.com/ar/al-mohamadia-compound | AQ7: 2026-10-11
A8: KHB-007 | B8: Zamil Village | D8: Al Khobar | E8: Al Qashlah | F8: 958F+CJ8, Al Qashlah, Al Khobar 34232 | G8: Open map | H8: 26.367623 | I8: 50.17397 | J8: Mixed Residential Compound | K8: Residential compound | L8: Operating (listed) | N8: 254 | O8: 168 apartments, 86 villas | P8: Gym Swimming Pool Kindergarten Reserved Parking Baby Nursery Library Beauty Salon Restaurant Ballroom Snack Bar Billiard Tables Squash Court Basketball Court Volleyball Court Wireless Internet Tennis Court Satellite Cable Pre-school Centre Recreation | Q8: https://zamilrealestate.com/en | R8: +966138136225 | T8: +966138136225 | U8: info@zamilre.com ; marketing@zamilre.com | Y8: https://x.com/ZamilGroup | Z8: Zamil Real Estate | AB8: Zamil Real Estate | AC8: Developer Managed | AD8: https://whichschooladvisor.com/saudi/area-guide/eastern-province/al-khobar | AE8: Verified | AF8: Marketing & leasing, Paid ad campaigns | AG8: 20 | AH8: 8 | AI8: 6 | AJ8: 15 | AK8: 10 | AL8: 5 | AM8: =SUM(AG8:AL8) -> 64 | AN8: =IF(AM8>=80,"A",IF(AM8>=60,"B","C")) -> B | AP8: https://rightcompound.com/compounds/khobar/zamil-village-residential-compound ; https://whichschooladvisor.com/saudi/area-guide/eastern-province/al-khobar ; https://zamilrealestate.com/en | AQ8: 2026-10-11
A9: KHB-008 | B9: Wadi Village | D9: Al Khobar | E9: Qurtubah | F9: Al Khobar | G9: Open map | H9: 26.249144 | I9: 50.160377 | J9: Luxury Residential Compound | K9: Residential compound | L9: Operating (listed) | N9: 52 | O9: Villas and apartments | P9: Gym Swimming Pool Reserved Parking Library Restaurant Billiard Tables Squash Court Basketball Court Volleyball Court Wireless Internet Tennis Court Satellite Cable Recreational Room Table Tennis Bus Transportation Garbage Chute Children Playground Pe | AC9: Third-Party Property Management | AE9: Not Available | AF9: Marketing & leasing, Social media management, Content & photography | AG9: 10 | AH9: 8 | AI9: 20 | AJ9: 0 | AK9: 0 | AL9: 5 | AM9: =SUM(AG9:AL9) -> 43 | AN9: =IF(AM9>=80,"A",IF(AM9>=60,"B","C")) -> C | AO9: WhichSchoolAdvisor says 'British management' (unnamed) and links to zamilrealestate.com; operator not confirmed. | AP9: https://rightcompound.com/compounds/khobar/al-wadi-village ; https://whichschooladvisor.com/saudi/area-guide/eastern-province/al-khobar | AQ9: 2026-10-11
A10: KHB-009 | B10: Arabian Village (Arabian Homes) | D10: Al Khobar | E10: Qurtubah | F10: Qutuba district , Al Khobar | G10: Open map | H10: 26.336099 | I10: 50.181813 | J10: Mixed Residential Compound | K10: Residential compound | L10: Operating (listed) | M10: 2008 | N10: 134 | O10: 108 apartments, 26 villas | P10: Gym Swimming Pool Reserved Parking Baby Nursery Library Restaurant Billiard Tables Squash Court Basketball Court Volleyball Court Wireless Internet Tennis Court Satellite Cable Recreational Room Table Tennis Bus Transportation Garbage Chute Children | AC10: Third-Party Property Management | AE10: Not Available | AF10: Marketing & leasing, Social media management, Content & photography | AG10: 15 | AH10: 8 | AI10: 20 | AJ10: 0 | AK10: 0 | AL10: 5 | AM10: =SUM(AG10:AL10) -> 48 | AN10: =IF(AM10>=80,"A",IF(AM10>=60,"B","C")) -> C | AO10: Units: 134 (WhichSchoolAdvisor) vs 126 (RightCompound). 'Managed by a British team' (unnamed). | AP10: https://rightcompound.com/compounds/khobar/arabian-homes-al-khobar ; https://whichschooladvisor.com/saudi/area-guide/eastern-province/al-khobar | AQ10: 2026-10-11
A11: KHB-010 | B11: Retal Residence | D11: Al Khobar | E11: Al Rakah | F11: Retal Residence - 9268 Salma Bin Suliman Str. | G11: Open map | H11: 26.377357 | I11: 50.218291 | J11: Mixed Residential Compound | K11: Residential compound | L11: Operating (listed) | P11: Gym Swimming Pool Kindergarten Reserved Parking Baby Nursery Library Beauty Salon Restaurant Ballroom Snack Bar Billiard Tables Squash Court Basketball Court Volleyball Court Wireless Internet Tennis Court Satellite Cable Pre-school Centre Commercial | Q11: https://www.retalresidence.com/ | R11: +966138259600 | T11: +966562416136 | U11: info@retalresidence.com ; sales@retalresidence.com | AC11: Unknown | AE11: Verified | AF11: Property management, Marketing & leasing, Social media management | AG11: 0 | AH11: 8 | AI11: 12 | AJ11: 15 | AK11: 0 | AL11: 5 | AM11: =SUM(AG11:AL11) -> 40 | AN11: =IF(AM11>=80,"A",IF(AM11>=60,"B","C")) -> C | AP11: https://rightcompound.com/compounds/khobar/retal-residence ; https://compoundin.com/rent/listing/1/0/0-0 ; https://www.retalresidence.com/ | AQ11: 2026-10-11
A12: KHB-011 | B12: Grand Village | C12: جراند فيلج | D12: Al Khobar | E12: North Khobar (Prince Saud Al Faisal Rd) | J12: Luxury Residential Compound | K12: Residential compound | L12: Operating (listed) | O12: Villas, townhouses, duplexes (furnished) | Q12: https://www.grandvillage.com.sa/ | S12: +966551222424 | U12: info@grandvillage.com.sa | AC12: Unknown | AE12: Cross-Checked | AF12: Property management, Marketing & leasing, Social media management | AG12: 0 | AH12: 8 | AI12: 12 | AJ12: 15 | AK12: 0 | AL12: 0 | AM12: =SUM(AG12:AL12) -> 35 | AN12: =IF(AM12>=80,"A",IF(AM12>=60,"B","C")) -> C | AP12: https://www.propertyfinder.sa/blog/%D9%83%D9%85%D8%A8%D9%88%D9%86%D8%AF%D8%A7%D8%AA-%D8%A7%D9%84%D8%AE%D8%A8%D8%B1-%D9%85%D8%AC%D9%85%D8%B9%D8%A7%D8%AA-%D8%B3%D9%83%D9%86%D9%8A%D8%A9-%D8%B9%D8%A7%D9%84%D9%85%D9%8A%D8%A9-%D8%B9%D9%84/ ; https://www.grandvillage.com.sa/ | AQ12: 2026-10-11
A13: KHB-012 | B13: Alef Compound | D13: Al Khobar | E13: Ishbiliya / Aziziyah | F13: Ishbilia district, Aziziah | G13: Open map | H13: 26.200387 | I13: 50.215008 | J13: Villa Compound | K13: Residential compound | L13: Operating (listed) | P13: Gym Swimming Pool Kindergarten Reserved Parking Baby Nursery Restaurant Snack Bar Billiard Tables Wireless Internet Satellite Cable Recreational Room Table Tennis Bus Transportation Garbage Chute Children Playground Pest Control Security 24/7 Laundry | Q13: https://alef-home.com/ | U13: info@alef-home.com | V13: https://www.instagram.com/alefkhobar | W13: https://www.facebook.com/Alef-Home-Compound-Khobar-Saudi-Arabia-105496395332383 | Y13: https://twitter.com/AlefHome | AC13: Unknown | AE13: Verified | AF13: Property management, Marketing & leasing, Paid ad campaigns | AG13: 0 | AH13: 8 | AI13: 6 | AJ13: 10 | AK13: 0 | AL13: 5 | AM13: =SUM(AG13:AL13) -> 29 | AN13: =IF(AM13>=80,"A",IF(AM13>=60,"B","C")) -> C | AP13: https://rightcompound.com/compounds/khobar/alef-compound ; https://www.expat.com/en/forum/middle-east/saudi-arabia/khobar/778968-list-of-some-compounds-in-al-khobar-ksa.html ; https://alef-home.com/ | AQ13: 2026-10-11
A14: KHB-013 | B14: Al Ansari Compound One | D14: Al Khobar | F14: Al Khobar | G14: Open map | H14: 26.338191 | I14: 50.179667 | J14: Mixed Residential Compound | K14: Residential compound | L14: Operating (listed) | P14: Gym Swimming Pool Kindergarten Reserved Parking Baby Nursery Billiard Tables Squash Court Basketball Court Volleyball Court Wireless Internet Tennis Court Satellite Cable Recreational Room Bus Transportation Garbage Chute Children Playground Pest Con | Q14: https://alansari.com.sa/ | R14: +966138098913 | S14: +966531223352 | U14: info@alansari.com | X14: https://www.linkedin.com/company/al-ansari-holding-group | Z14: Al Ansari Holding Group (name association) | AB14: Abyan Real Estate Company | AC14: Third-Party Property Management | AD14: https://rightcompound.com/compounds/khobar/al-ansary-compound | AE14: Unverified | AF14: Marketing & leasing, Paid ad campaigns | AG14: 0 | AH14: 8 | AI14: 6 | AJ14: 5 | AK14: 10 | AL14: 5 | AM14: =SUM(AG14:AL14) -> 34 | AN14: =IF(AM14>=80,"A",IF(AM14>=60,"B","C")) -> C | AO14: Owner link to Al Ansari Holding inferred from WhichSchoolAdvisor linking alansari.com.sa; not confirmed. | AP14: https://rightcompound.com/compounds/khobar/al-ansary-compound ; https://www.expat.com/en/forum/middle-east/saudi-arabia/khobar/778968-list-of-some-compounds-in-al-khobar-ksa.html ; https://alansari.com.sa/contact-us/ | AQ14: 2026-10-11
A15: KHB-014 | B15: Al Ansari Compound Two | D15: Al Khobar | E15: Beside French School of Khobar | F15: Al Khobar, beside the French school of Khobar | G15: Open map | H15: 26.324749 | I15: 50.192349 | J15: Mixed Residential Compound | K15: Residential compound | L15: Operating (listed) | N15: 86 | O15: 1-3 bed apartments, 3-bed villas | P15: Gym Swimming Pool Kindergarten Reserved Parking Snack Bar Billiard Tables Squash Court Basketball Court Volleyball Court Wireless Internet Tennis Court Satellite Cable Recreational Room Business Centre Table Tennis Bus Transportation Garbage Chute Ch | Q15: https://alansari.com.sa/ | S15: +966531223352 | AB15: Abyan Real Estate Company | AC15: Third-Party Property Management | AD15: https://rightcompound.com/compounds/khobar/al-ansari-compound-two-al-khobar | AE15: Unverified | AF15: Marketing & leasing, Social media management | AG15: 10 | AH15: 8 | AI15: 12 | AJ15: 5 | AK15: 10 | AL15: 5 | AM15: =SUM(AG15:AL15) -> 50 | AN15: =IF(AM15>=80,"A",IF(AM15>=60,"B","C")) -> C | AP15: https://rightcompound.com/compounds/khobar/al-ansari-compound-two-al-khobar ; https://whichschooladvisor.com/saudi/area-guide/eastern-province/al-khobar | AQ15: 2026-10-11
